{"version":3,"sources":["js/01-try-catch.js"],"names":["console","log","myVar","error","dir"],"mappings":";AAeA,IACEA,QAAQC,IAAI,2BAEZC,MAEAF,QAAQC,IAAI,0BACZ,MAAOE,GACPH,QAAQI,IAAID,GACZH,QAAQC,IAAI,UAGdD,QAAQC,IAAI","file":"01-try-catch.4466075a.js","sourceRoot":"../src","sourcesContent":["// Обработка ошибок с try...catch\n//  - Синтаксис\n//  - Какие ошибки ловит\n//    - ❌ ошибки парсинга (parsing errors)\n//    - ✅ ошибки выполнения (runtime errors)\n//  - Ловит только ошибки в синхронном коде\n//    - Как словить ошибку в асинхронном коде\n//  - Объект ошибки\n//    - name\n//    - message\n//    - stack\n//  - Блок catch без объекта ошибки\n\n// only sync code\n\ntry {\n  console.log('inside TRY before myVar');\n\n  myVar;\n\n  console.log('inside TRY after myVar');\n} catch (error) {\n  console.dir(error);\n  console.log('Error!');\n}\n\nconsole.log('After try..catch');\n\n// setTimeout(() => {\n//   try {\n//     myVar;\n//   } catch (error) {\n//     console.log('Async ERROR!');\n//   }\n// }, 1000);\n"]}